[2023-08-24T05:21:48.455+0000] {taskinstance.py:1103} INFO - Dependencies all met for dep_context=non-requeueable deps ti=<TaskInstance: 17_base_hook.insert_postgres manual__2023-08-24T05:16:29.146510+00:00 [queued]>
[2023-08-24T05:21:48.467+0000] {taskinstance.py:1103} INFO - Dependencies all met for dep_context=requeueable deps ti=<TaskInstance: 17_base_hook.insert_postgres manual__2023-08-24T05:16:29.146510+00:00 [queued]>
[2023-08-24T05:21:48.467+0000] {taskinstance.py:1308} INFO - Starting attempt 4 of 4
[2023-08-24T05:21:48.490+0000] {taskinstance.py:1327} INFO - Executing <Task(PythonOperator): insert_postgres> on 2023-08-24 05:16:29.146510+00:00
[2023-08-24T05:21:48.497+0000] {standard_task_runner.py:57} INFO - Started process 1360 to run task
[2023-08-24T05:21:48.501+0000] {standard_task_runner.py:84} INFO - Running: ['***', 'tasks', 'run', '17_base_hook', 'insert_postgres', 'manual__2023-08-24T05:16:29.146510+00:00', '--job-id', '220', '--raw', '--subdir', 'DAGS_FOLDER/17_base_hook.py', '--cfg-path', '/tmp/tmpqp2c_l2z']
[2023-08-24T05:21:48.502+0000] {standard_task_runner.py:85} INFO - Job 220: Subtask insert_postgres
[2023-08-24T05:21:48.557+0000] {task_command.py:410} INFO - Running <TaskInstance: 17_base_hook.insert_postgres manual__2023-08-24T05:16:29.146510+00:00 [running]> on host 8c493a5ffb5d
[2023-08-24T05:21:48.659+0000] {taskinstance.py:1547} INFO - Exporting env vars: AIRFLOW_CTX_DAG_OWNER='***' AIRFLOW_CTX_DAG_ID='17_base_hook' AIRFLOW_CTX_TASK_ID='insert_postgres' AIRFLOW_CTX_EXECUTION_DATE='2023-08-24T05:16:29.146510+00:00' AIRFLOW_CTX_TRY_NUMBER='4' AIRFLOW_CTX_DAG_RUN_ID='manual__2023-08-24T05:16:29.146510+00:00'
[2023-08-24T05:21:48.661+0000] {custom_postgres_hook.py:34} INFO - NumCorona에 /opt/***/files/corona/20230824/num_corona.csv을 적재합니다
[2023-08-24T05:21:48.672+0000] {base.py:73} INFO - Using connection ID 'conn-custom-postgres' for task execution.
[2023-08-24T05:21:48.673+0000] {taskinstance.py:1824} ERROR - Task failed with exception
Traceback (most recent call last):
  File "/home/airflow/.local/lib/python3.7/site-packages/airflow/operators/python.py", line 181, in execute
    return_value = self.execute_callable()
  File "/home/airflow/.local/lib/python3.7/site-packages/airflow/operators/python.py", line 198, in execute_callable
    return self.python_callable(*self.op_args, **self.op_kwargs)
  File "/opt/airflow/dags/17_base_hook.py", line 18, in insert_postgres
    table=table, file_name=file_name, delimiter=",", is_header=True, is_replace=True)
  File "/opt/airflow/plugins/hooks/custom_postgres_hook.py", line 35, in bulk_load
    self.get_conn()
  File "/opt/airflow/plugins/hooks/custom_postgres_hook.py", line 19, in get_conn
    host=self.host, user=self.user, password=self.password, schema=self.schema, port=self.port)
  File "/home/airflow/.local/lib/python3.7/site-packages/psycopg2/__init__.py", line 121, in connect
    dsn = _ext.make_dsn(dsn, **kwargs)
  File "/home/airflow/.local/lib/python3.7/site-packages/psycopg2/extensions.py", line 167, in make_dsn
    parse_dsn(dsn)
psycopg2.ProgrammingError: invalid dsn: invalid connection option "schema"

[2023-08-24T05:21:48.683+0000] {taskinstance.py:1350} INFO - Marking task as FAILED. dag_id=17_base_hook, task_id=insert_postgres, execution_date=20230824T051629, start_date=20230824T052148, end_date=20230824T052148
[2023-08-24T05:21:48.700+0000] {standard_task_runner.py:109} ERROR - Failed to execute job 220 for task insert_postgres (invalid dsn: invalid connection option "schema"
; 1360)
[2023-08-24T05:21:48.713+0000] {local_task_job_runner.py:225} INFO - Task exited with return code 1
[2023-08-24T05:21:48.736+0000] {taskinstance.py:2653} INFO - 0 downstream tasks scheduled from follow-on schedule check
