[2023-08-24T05:17:24.368+0000] {taskinstance.py:1103} INFO - Dependencies all met for dep_context=non-requeueable deps ti=<TaskInstance: 17_base_hook.insert_postgres manual__2023-08-24T05:16:29.146510+00:00 [queued]>
[2023-08-24T05:17:24.381+0000] {taskinstance.py:1103} INFO - Dependencies all met for dep_context=requeueable deps ti=<TaskInstance: 17_base_hook.insert_postgres manual__2023-08-24T05:16:29.146510+00:00 [queued]>
[2023-08-24T05:17:24.382+0000] {taskinstance.py:1308} INFO - Starting attempt 2 of 2
[2023-08-24T05:17:24.408+0000] {taskinstance.py:1327} INFO - Executing <Task(PythonOperator): insert_postgres> on 2023-08-24 05:16:29.146510+00:00
[2023-08-24T05:17:24.415+0000] {standard_task_runner.py:57} INFO - Started process 1281 to run task
[2023-08-24T05:17:24.418+0000] {standard_task_runner.py:84} INFO - Running: ['***', 'tasks', 'run', '17_base_hook', 'insert_postgres', 'manual__2023-08-24T05:16:29.146510+00:00', '--job-id', '218', '--raw', '--subdir', 'DAGS_FOLDER/17_base_hook.py', '--cfg-path', '/tmp/tmpnm9ojtw9']
[2023-08-24T05:17:24.419+0000] {standard_task_runner.py:85} INFO - Job 218: Subtask insert_postgres
[2023-08-24T05:17:24.474+0000] {task_command.py:410} INFO - Running <TaskInstance: 17_base_hook.insert_postgres manual__2023-08-24T05:16:29.146510+00:00 [running]> on host 8c493a5ffb5d
[2023-08-24T05:17:24.578+0000] {taskinstance.py:1547} INFO - Exporting env vars: AIRFLOW_CTX_DAG_OWNER='***' AIRFLOW_CTX_DAG_ID='17_base_hook' AIRFLOW_CTX_TASK_ID='insert_postgres' AIRFLOW_CTX_EXECUTION_DATE='2023-08-24T05:16:29.146510+00:00' AIRFLOW_CTX_TRY_NUMBER='2' AIRFLOW_CTX_DAG_RUN_ID='manual__2023-08-24T05:16:29.146510+00:00'
[2023-08-24T05:17:24.579+0000] {taskinstance.py:1824} ERROR - Task failed with exception
Traceback (most recent call last):
  File "/home/airflow/.local/lib/python3.7/site-packages/airflow/operators/python.py", line 181, in execute
    return_value = self.execute_callable()
  File "/home/airflow/.local/lib/python3.7/site-packages/airflow/operators/python.py", line 198, in execute_callable
    return self.python_callable(*self.op_args, **self.op_kwargs)
  File "/opt/airflow/dags/17_base_hook.py", line 18, in insert_postgres
    table=table, file_name=file_name, delimiter=",", header=True, is_replace=True)
TypeError: bulk_load() got an unexpected keyword argument 'header'
[2023-08-24T05:17:24.591+0000] {taskinstance.py:1350} INFO - Marking task as FAILED. dag_id=17_base_hook, task_id=insert_postgres, execution_date=20230824T051629, start_date=20230824T051724, end_date=20230824T051724
[2023-08-24T05:17:24.608+0000] {standard_task_runner.py:109} ERROR - Failed to execute job 218 for task insert_postgres (bulk_load() got an unexpected keyword argument 'header'; 1281)
[2023-08-24T05:17:24.631+0000] {local_task_job_runner.py:225} INFO - Task exited with return code 1
[2023-08-24T05:17:24.657+0000] {taskinstance.py:2653} INFO - 0 downstream tasks scheduled from follow-on schedule check
