[2023-08-24T01:17:52.616+0000] {taskinstance.py:1103} INFO - Dependencies all met for dep_context=non-requeueable deps ti=<TaskInstance: 13_trigger_rule.upstream1 manual__2023-08-24T01:17:50.322059+00:00 [queued]>
[2023-08-24T01:17:52.629+0000] {taskinstance.py:1103} INFO - Dependencies all met for dep_context=requeueable deps ti=<TaskInstance: 13_trigger_rule.upstream1 manual__2023-08-24T01:17:50.322059+00:00 [queued]>
[2023-08-24T01:17:52.629+0000] {taskinstance.py:1308} INFO - Starting attempt 1 of 1
[2023-08-24T01:17:52.650+0000] {taskinstance.py:1327} INFO - Executing <Task(_PythonDecoratedOperator): upstream1> on 2023-08-24 01:17:50.322059+00:00
[2023-08-24T01:17:52.659+0000] {standard_task_runner.py:57} INFO - Started process 2606 to run task
[2023-08-24T01:17:52.662+0000] {standard_task_runner.py:84} INFO - Running: ['***', 'tasks', 'run', '13_trigger_rule', 'upstream1', 'manual__2023-08-24T01:17:50.322059+00:00', '--job-id', '190', '--raw', '--subdir', 'DAGS_FOLDER/13_trigger_rule.py', '--cfg-path', '/tmp/tmptcwre9yu']
[2023-08-24T01:17:52.663+0000] {standard_task_runner.py:85} INFO - Job 190: Subtask upstream1
[2023-08-24T01:17:52.757+0000] {task_command.py:410} INFO - Running <TaskInstance: 13_trigger_rule.upstream1 manual__2023-08-24T01:17:50.322059+00:00 [running]> on host 05c492c53b17
[2023-08-24T01:17:52.930+0000] {taskinstance.py:1547} INFO - Exporting env vars: AIRFLOW_CTX_DAG_OWNER='***' AIRFLOW_CTX_DAG_ID='13_trigger_rule' AIRFLOW_CTX_TASK_ID='upstream1' AIRFLOW_CTX_EXECUTION_DATE='2023-08-24T01:17:50.322059+00:00' AIRFLOW_CTX_TRY_NUMBER='1' AIRFLOW_CTX_DAG_RUN_ID='manual__2023-08-24T01:17:50.322059+00:00'
[2023-08-24T01:17:52.950+0000] {taskinstance.py:1824} ERROR - Task failed with exception
Traceback (most recent call last):
  File "/home/airflow/.local/lib/python3.7/site-packages/airflow/decorators/base.py", line 220, in execute
    return_value = super().execute(context)
  File "/home/airflow/.local/lib/python3.7/site-packages/airflow/operators/python.py", line 181, in execute
    return_value = self.execute_callable()
  File "/home/airflow/.local/lib/python3.7/site-packages/airflow/operators/python.py", line 198, in execute_callable
    return self.python_callable(*self.op_args, **self.op_kwargs)
  File "/opt/airflow/dags/13_trigger_rule.py", line 24, in upstream1
    raise AirflowException("raise exception")
airflow.exceptions.AirflowException: raise exception
[2023-08-24T01:17:52.959+0000] {taskinstance.py:1350} INFO - Marking task as FAILED. dag_id=13_trigger_rule, task_id=upstream1, execution_date=20230824T011750, start_date=20230824T011752, end_date=20230824T011752
[2023-08-24T01:17:52.981+0000] {standard_task_runner.py:109} ERROR - Failed to execute job 190 for task upstream1 (raise exception; 2606)
[2023-08-24T01:17:53.035+0000] {local_task_job_runner.py:225} INFO - Task exited with return code 1
[2023-08-24T01:17:53.074+0000] {taskinstance.py:2653} INFO - 0 downstream tasks scheduled from follow-on schedule check
